Rudolph Van Staden, [8/12/2025 12:32 PM]
C:\Users\rudolph.vanstaden\EG_v1>git pull https://github.com/Rudolph001/EG_v1.git
remote: Enumerating objects: 13, done.
remote: Counting objects: 100% (13/13), done.
remote: Compressing objects: 100% (3/3), done.
remote: Total 8 (delta 5), reused 8 (delta 5), pack-reused 0 (from 0)
Unpacking objects: 100% (8/8), 3.30 KiB | 135.00 KiB/s, done.
From https://github.com/Rudolph001/EG_v1
 * branch            HEAD       -> FETCH_HEAD
Updating 3e17e1d..cac3b8d
Fast-forward
 README_LOCAL.md                                    |   6 +-
 ...ng-up-database--1754994575854_1754994575854.txt | 164 +++++++++++++++++++++
 install_mac.sh                                     |   4 +-
 install_windows.bat                                |   4 +-
 run_local_fixed.py                                 |  62 ++++++++
 5 files changed, 233 insertions(+), 7 deletions(-)
 create mode 100644 attached_assets/Pasted-Rudolph-Van-Staden-8-12-2025-12-29-PM-Setting-up-database--1754994575854_1754994575854.txt
 create mode 100644 run_local_fixed.py

C:\Users\rudolph.vanstaden\EG_v1>run_local_fixed.py
========================================
Email Guardian - Local Development Server
========================================

Database: sqlite:///instance/email_guardian.db
Starting server on http://localhost:5000
Press Ctrl+C to stop the server

Error starting server: (sqlite3.OperationalError) unable to open database file
(Background on this error at: https://sqlalche.me/e/20/e3q8)

Troubleshooting:
1. Make sure database was initialized: python setup_database.py
2. Check that all packages are installed
3. Verify you're in the project root directory

C:\Users\rudolph.vanstaden\EG_v1>run_local.py
Traceback (most recent call last):
  File "C:\Users\rudolph.vanstaden\AppData\Local\Programs\Python\Python313\Lib\site-packages\sqlalchemy\engine\base.py", line 143, in init
    self._dbapi_connection = engine.raw_connection()
                             ~~~~~~~~~~~~~~~~~~~~~^^
  File "C:\Users\rudolph.vanstaden\AppData\Local\Programs\Python\Python313\Lib\site-packages\sqlalchemy\engine\base.py", line 3295, in raw_connection
    return self.pool.connect()
           ~~~~~~~~~~~~~~~~~^^
  File "C:\Users\rudolph.vanstaden\AppData\Local\Programs\Python\Python313\Lib\site-packages\sqlalchemy\pool\base.py", line 447, in connect
    return _ConnectionFairy._checkout(self)
           ~~~~~~~~~~~~~~~~~~~~~~~~^^^^^^
  File "C:\Users\rudolph.vanstaden\AppData\Local\Programs\Python\Python313\Lib\site-packages\sqlalchemy\pool\base.py", line 1264, in _checkout
    fairy = _ConnectionRecord.checkout(pool)
  File "C:\Users\rudolph.vanstaden\AppData\Local\Programs\Python\Python313\Lib\site-packages\sqlalchemy\pool\base.py", line 711, in checkout
    rec = pool._do_get()
  File "C:\Users\rudolph.vanstaden\AppData\Local\Programs\Python\Python313\Lib\site-packages\sqlalchemy\pool\impl.py", line 177, in _do_get
    with util.safe_reraise():
         ~~~~~~~~~~~~~~~^^
  File "C:\Users\rudolph.vanstaden\AppData\Local\Programs\Python\Python313\Lib\site-packages\sqlalchemy\util\langhelpers.py", line 224, in exit
    raise exc_value.with_traceback(exc_tb)
  File "C:\Users\rudolph.vanstaden\AppData\Local\Programs\Python\Python313\Lib\site-packages\sqlalchemy\pool\impl.py", line 175, in _do_get
    return self._create_connection()
           ~~~~~~~~~~~~~~~~~~~~~~~^^
  File "C:\Users\rudolph.vanstaden\AppData\Local\Programs\Python\Python313\Lib\site-packages\sqlalchemy\pool\base.py", line 388, in _create_connection
    return _ConnectionRecord(self)
  File "C:\Users\rudolph.vanstaden\AppData\Local\Programs\Python\Python313\Lib\site-packages\sqlalchemy\pool\base.py", line 673, in init
    self.connect()
    ~~~~~~~~~~~~~~^^
  File "C:\Users\rudolph.vanstaden\AppData\Local\Programs\Python\Python313\Lib\site-packages\sqlalchemy\pool\base.py", line 899, in __connect
    with util.safe_reraise():
         ~~~~~~~~~~~~~~~~~^^
  File "C:\Users\rudolph.vanstaden\AppData\Local\Programs\Python\Python313\Lib\site-packages\sqlalchemy\util\langhelpers.py", line 224, in __exit

Rudolph Van Staden, [8/12/2025 12:32 PM]
raise exc_value.with_traceback(exc_tb)
  File "C:\Users\rudolph.vanstaden\AppData\Local\Programs\Python\Python313\Lib\site-packages\sqlalchemy\pool\base.py", line 895, in connect
    self.dbapi_connection = connection = pool._invoke_creator(self)
                                         ~~~~~~~~~~~~~~~~~~~~^^^^^^
  File "C:\Users\rudolph.vanstaden\AppData\Local\Programs\Python\Python313\Lib\site-packages\sqlalchemy\engine\create.py", line 646, in connect
    return dialect.connect(*cargs, **cparams)
           ~~~~~~~~~~~~~~~^^^^^^^^^^^^^^^^^^^
  File "C:\Users\rudolph.vanstaden\AppData\Local\Programs\Python\Python313\Lib\site-packages\sqlalchemy\engine\default.py", line 626, in connect
    return self.loaded_dbapi.connect(*cargs, **cparams)  # type: ignore[no-any-return]  # NOQA: E501
           ~~~~~~~~~~~~~~~~~~~~~~~~~^^^^^^^^^^^^^^^^^^^
sqlite3.OperationalError: unable to open database file

The above exception was the direct cause of the following exception:

Traceback (most recent call last):
  File "C:\Users\rudolph.vanstaden\EG_v1\run_local.py", line 10, in <module>
    from app import app
  File "C:\Users\rudolph.vanstaden\EG_v1\app.py", line 45, in <module>
    db.create_all()
    ~~~~~~~~~~~~~^^
  File "C:\Users\rudolph.vanstaden\AppData\Local\Programs\Python\Python313\Lib\site-packages\flask_sqlalchemy\extension.py", line 900, in create_all
    self._call_for_binds(bind_key, "create_all")
    ~~~~~~~~~~~~~~~~~~~~^^^^^^^^^^^^^^^^^^^^^^^^
  File "C:\Users\rudolph.vanstaden\AppData\Local\Programs\Python\Python313\Lib\site-packages\flask_sqlalchemy\extension.py", line 881, in _call_for_binds
    getattr(metadata, op_name)(bind=engine)
    ~~~~~~~~~~~~~~~~~~~~~~~~~~^^^^^^^^^^^^^
  File "C:\Users\rudolph.vanstaden\AppData\Local\Programs\Python\Python313\Lib\site-packages\sqlalchemy\sql\schema.py", line 5924, in create_all
    bind._run_ddl_visitor(
    ~~~~~~~~~~~~~~~~~~~~~^
        ddl.SchemaGenerator, self, checkfirst=checkfirst, tables=tables
        ^^^^^^^^^^^^^^^^^^^^^^^^^^^^^^^^^^^^^^^^^^^^^^^^^^^^^^^^^^^^^^^
    )
    ^
  File "C:\Users\rudolph.vanstaden\AppData\Local\Programs\Python\Python313\Lib\site-packages\sqlalchemy\engine\base.py", line 3245, in _run_ddl_visitor
    with self.begin() as conn:
         ~~~~~~~~~~^^
  File "C:\Users\rudolph.vanstaden\AppData\Local\Programs\Python\Python313\Lib\contextlib.py", line 141, in __enter
    return next(self.gen)
  File "C:\Users\rudolph.vanstaden\AppData\Local\Programs\Python\Python313\Lib\site-packages\sqlalchemy\engine\base.py", line 3235, in begin
    with self.connect() as conn:
         ~~~~~~~~~~^^
  File "C:\Users\rudolph.vanstaden\AppData\Local\Programs\Python\Python313\Lib\site-packages\sqlalchemy\engine\base.py", line 3271, in connect
    return self._connection_cls(self)
           ~~~~~~~~~~~~~~~~^^^^^^
  File "C:\Users\rudolph.vanstaden\AppData\Local\Programs\Python\Python313\Lib\site-packages\sqlalchemy\engine\base.py", line 145, in __init__
    Connection._handle_dbapi_exception_noconnection(
    ~~~~~~~~~~~~~~~~~~~~~~~~~~~~~~~~~~~~~~~~~~~~~^
        err, dialect, engine
        ^^^^^^^^^^^^^^^^^^^^
    )
    ^
  File "C:\Users\rudolph.vanstaden\AppData\Local\Programs\Python\Python313\Lib\site-packages\sqlalchemy\engine\base.py", line 2434, in _handle_dbapi_exception_noconnection
    raise sqlalchemy_exception.with_traceback(exc_info[2]) from e
  File "C:\Users\rudolph.vanstaden\AppData\Local\Programs\Python\Python313\Lib\site-packages\sqlalchemy\engine\base.py", line 143, in init
    self._dbapi_connection = engine.raw_connection()
                             ~~~~~~~~~~~~~~~~~~~~~^^
  File "C:\Users\rudolph.vanstaden\AppData\Local\Programs\Python\Python313\Lib\site-packages\sqlalchemy\engine\base.py", line 3295, in raw_connection
    return self.pool.connect()
           ~~~~~~~~~~~~~~~~~^^
  File "C:\Users\rudolph.vanstaden\AppData\Local\Programs\Python\Python313\Lib\site-packages\sqlalchemy\pool\base.py", line 447, in connect
    return _ConnectionFairy._checkout(self)

Rudolph Van Staden, [8/12/2025 12:32 PM]
~~~~~~~~~~~~~~~~~~~~~~~~^^^^^^
  File "C:\Users\rudolph.vanstaden\AppData\Local\Programs\Python\Python313\Lib\site-packages\sqlalchemy\pool\base.py", line 1264, in _checkout
    fairy = _ConnectionRecord.checkout(pool)
  File "C:\Users\rudolph.vanstaden\AppData\Local\Programs\Python\Python313\Lib\site-packages\sqlalchemy\pool\base.py", line 711, in checkout
    rec = pool._do_get()
  File "C:\Users\rudolph.vanstaden\AppData\Local\Programs\Python\Python313\Lib\site-packages\sqlalchemy\pool\impl.py", line 177, in _do_get
    with util.safe_reraise():
         ~~~~~~~~~~~~~~~^^
  File "C:\Users\rudolph.vanstaden\AppData\Local\Programs\Python\Python313\Lib\site-packages\sqlalchemy\util\langhelpers.py", line 224, in exit
    raise exc_value.with_traceback(exc_tb)
  File "C:\Users\rudolph.vanstaden\AppData\Local\Programs\Python\Python313\Lib\site-packages\sqlalchemy\pool\impl.py", line 175, in _do_get
    return self._create_connection()
           ~~~~~~~~~~~~~~~~~~~~~~~^^
  File "C:\Users\rudolph.vanstaden\AppData\Local\Programs\Python\Python313\Lib\site-packages\sqlalchemy\pool\base.py", line 388, in _create_connection
    return _ConnectionRecord(self)
  File "C:\Users\rudolph.vanstaden\AppData\Local\Programs\Python\Python313\Lib\site-packages\sqlalchemy\pool\base.py", line 673, in init
    self.connect()
    ~~~~~~~~~~~~~~^^
  File "C:\Users\rudolph.vanstaden\AppData\Local\Programs\Python\Python313\Lib\site-packages\sqlalchemy\pool\base.py", line 899, in __connect
    with util.safe_reraise():
         ~~~~~~~~~~~~~~~~~^^
  File "C:\Users\rudolph.vanstaden\AppData\Local\Programs\Python\Python313\Lib\site-packages\sqlalchemy\util\langhelpers.py", line 224, in __exit
    raise exc_value.with_traceback(exc_tb)
  File "C:\Users\rudolph.vanstaden\AppData\Local\Programs\Python\Python313\Lib\site-packages\sqlalchemy\pool\base.py", line 895, in __connect
    self.dbapi_connection = connection = pool._invoke_creator(self)
                                         ~~~~~~~~~~~~~~~~~~^^^^^^
  File "C:\Users\rudolph.vanstaden\AppData\Local\Programs\Python\Python313\Lib\site-packages\sqlalchemy\engine\create.py", line 646, in connect
    return dialect.connect(*cargs, **cparams)
           ~~~~~~~~~~~~~^^^^^^^^^^^^^^^^^^^
  File "C:\Users\rudolph.vanstaden\AppData\Local\Programs\Python\Python313\Lib\site-packages\sqlalchemy\engine\default.py", line 626, in connect
    return self.loaded_dbapi.connect(*cargs, **cparams)  # type: ignore[no-any-return]  # NOQA: E501
           ~~~~~~~~~~~~~~~~~~~~~~~~~^^^^^^^^^^^^^^^^^^^
sqlalchemy.exc.OperationalError: (sqlite3.OperationalError) unable to open database file
(Background on this error at: https://sqlalche.me/e/20/e3q8)