Rudolph Van Staden, [8/12/2025 12:29 PM]
Setting up database...
========================================
Email Guardian - Database Setup
========================================

Working directory: C:\Users\rudolph.vanstaden\EG_v1
Creating required directories...
✓ Created: C:\Users\rudolph.vanstaden\EG_v1\uploads
✓ Created: C:\Users\rudolph.vanstaden\EG_v1\instance
Database URL: sqlite:///C:/Users/rudolph.vanstaden/EG_v1/instance/email_guardian.db
Initializing database...
✓ SQLite connection test passed
✓ Database tables created successfully
✓ Database file created: C:\Users\rudolph.vanstaden\EG_v1\instance\email_guardian.db
✓ Database file size: 90112 bytes

✓ Database setup completed successfully!

You can now run the application with:
  python run_local.py

========================================
Installation completed successfully!
========================================

To run the application:
  python main.py

Then open your browser to: http://localhost:5000

Press any key to start the application now...
Press any key to continue . . .
Starting Email Guardian...
Traceback (most recent call last):
  File "C:\Users\rudolph.vanstaden\AppData\Local\Programs\Python\Python313\Lib\site-packages\sqlalchemy\engine\base.py", line 143, in init
    self._dbapi_connection = engine.raw_connection()
                             ~~~~~~~~~~~~~~~~~~~~~^^
  File "C:\Users\rudolph.vanstaden\AppData\Local\Programs\Python\Python313\Lib\site-packages\sqlalchemy\engine\base.py", line 3295, in raw_connection
    return self.pool.connect()
           ~~~~~~~~~~~~~~~~~^^
  File "C:\Users\rudolph.vanstaden\AppData\Local\Programs\Python\Python313\Lib\site-packages\sqlalchemy\pool\base.py", line 447, in connect
    return _ConnectionFairy._checkout(self)
           ~~~~~~~~~~~~~~~~~~~~~~~~^^^^^^
  File "C:\Users\rudolph.vanstaden\AppData\Local\Programs\Python\Python313\Lib\site-packages\sqlalchemy\pool\base.py", line 1264, in _checkout
    fairy = _ConnectionRecord.checkout(pool)
  File "C:\Users\rudolph.vanstaden\AppData\Local\Programs\Python\Python313\Lib\site-packages\sqlalchemy\pool\base.py", line 711, in checkout
    rec = pool._do_get()
  File "C:\Users\rudolph.vanstaden\AppData\Local\Programs\Python\Python313\Lib\site-packages\sqlalchemy\pool\impl.py", line 177, in _do_get
    with util.safe_reraise():
         ~~~~~~~~~~~~~~~^^
  File "C:\Users\rudolph.vanstaden\AppData\Local\Programs\Python\Python313\Lib\site-packages\sqlalchemy\util\langhelpers.py", line 224, in exit
    raise exc_value.with_traceback(exc_tb)
  File "C:\Users\rudolph.vanstaden\AppData\Local\Programs\Python\Python313\Lib\site-packages\sqlalchemy\pool\impl.py", line 175, in _do_get
    return self._create_connection()
           ~~~~~~~~~~~~~~~~~~~~~~~^^
  File "C:\Users\rudolph.vanstaden\AppData\Local\Programs\Python\Python313\Lib\site-packages\sqlalchemy\pool\base.py", line 388, in _create_connection
    return _ConnectionRecord(self)
  File "C:\Users\rudolph.vanstaden\AppData\Local\Programs\Python\Python313\Lib\site-packages\sqlalchemy\pool\base.py", line 673, in init
    self.connect()
    ~~~~~~~~~~~~~~^^
  File "C:\Users\rudolph.vanstaden\AppData\Local\Programs\Python\Python313\Lib\site-packages\sqlalchemy\pool\base.py", line 899, in __connect
    with util.safe_reraise():
         ~~~~~~~~~~~~~~~~~^^
  File "C:\Users\rudolph.vanstaden\AppData\Local\Programs\Python\Python313\Lib\site-packages\sqlalchemy\util\langhelpers.py", line 224, in __exit
    raise exc_value.with_traceback(exc_tb)

Rudolph Van Staden, [8/12/2025 12:29 PM]
File "C:\Users\rudolph.vanstaden\AppData\Local\Programs\Python\Python313\Lib\site-packages\sqlalchemy\pool\base.py", line 895, in connect
    self.dbapi_connection = connection = pool._invoke_creator(self)
                                         ~~~~~~~~~~~~~~~~~~~~^^^^^^
  File "C:\Users\rudolph.vanstaden\AppData\Local\Programs\Python\Python313\Lib\site-packages\sqlalchemy\engine\create.py", line 646, in connect
    return dialect.connect(*cargs, **cparams)
           ~~~~~~~~~~~~~~~^^^^^^^^^^^^^^^^^^^
  File "C:\Users\rudolph.vanstaden\AppData\Local\Programs\Python\Python313\Lib\site-packages\sqlalchemy\engine\default.py", line 626, in connect
    return self.loaded_dbapi.connect(*cargs, **cparams)  # type: ignore[no-any-return]  # NOQA: E501
           ~~~~~~~~~~~~~~~~~~~~~~~~~^^^^^^^^^^^^^^^^^^^
sqlite3.OperationalError: unable to open database file

The above exception was the direct cause of the following exception:

Traceback (most recent call last):
  File "C:\Users\rudolph.vanstaden\EG_v1\main.py", line 1, in <module>
    from app import app
  File "C:\Users\rudolph.vanstaden\EG_v1\app.py", line 45, in <module>
    db.create_all()
    ~~~~~~~~~~~~~^^
  File "C:\Users\rudolph.vanstaden\AppData\Local\Programs\Python\Python313\Lib\site-packages\flask_sqlalchemy\extension.py", line 900, in create_all
    self._call_for_binds(bind_key, "create_all")
    ~~~~~~~~~~~~~~~~~~~~^^^^^^^^^^^^^^^^^^^^^^^^
  File "C:\Users\rudolph.vanstaden\AppData\Local\Programs\Python\Python313\Lib\site-packages\flask_sqlalchemy\extension.py", line 881, in _call_for_binds
    getattr(metadata, op_name)(bind=engine)
    ~~~~~~~~~~~~~~~~~~~~~~~~~~^^^^^^^^^^^^^
  File "C:\Users\rudolph.vanstaden\AppData\Local\Programs\Python\Python313\Lib\site-packages\sqlalchemy\sql\schema.py", line 5924, in create_all
    bind._run_ddl_visitor(
    ~~~~~~~~~~~~~~~~~~~~~^
        ddl.SchemaGenerator, self, checkfirst=checkfirst, tables=tables
        ^^^^^^^^^^^^^^^^^^^^^^^^^^^^^^^^^^^^^^^^^^^^^^^^^^^^^^^^^^^^^^^
    )
    ^
  File "C:\Users\rudolph.vanstaden\AppData\Local\Programs\Python\Python313\Lib\site-packages\sqlalchemy\engine\base.py", line 3245, in _run_ddl_visitor
    with self.begin() as conn:
         ~~~~~~~~~~^^
  File "C:\Users\rudolph.vanstaden\AppData\Local\Programs\Python\Python313\Lib\contextlib.py", line 141, in __enter
    return next(self.gen)
  File "C:\Users\rudolph.vanstaden\AppData\Local\Programs\Python\Python313\Lib\site-packages\sqlalchemy\engine\base.py", line 3235, in begin
    with self.connect() as conn:
         ~~~~~~~~~~^^
  File "C:\Users\rudolph.vanstaden\AppData\Local\Programs\Python\Python313\Lib\site-packages\sqlalchemy\engine\base.py", line 3271, in connect
    return self._connection_cls(self)
           ~~~~~~~~~~~~~~~~^^^^^^
  File "C:\Users\rudolph.vanstaden\AppData\Local\Programs\Python\Python313\Lib\site-packages\sqlalchemy\engine\base.py", line 145, in __init__
    Connection._handle_dbapi_exception_noconnection(
    ~~~~~~~~~~~~~~~~~~~~~~~~~~~~~~~~~~~~~~~~~~~~~^
        err, dialect, engine
        ^^^^^^^^^^^^^^^^^^^^
    )
    ^
  File "C:\Users\rudolph.vanstaden\AppData\Local\Programs\Python\Python313\Lib\site-packages\sqlalchemy\engine\base.py", line 2434, in _handle_dbapi_exception_noconnection
    raise sqlalchemy_exception.with_traceback(exc_info[2]) from e
  File "C:\Users\rudolph.vanstaden\AppData\Local\Programs\Python\Python313\Lib\site-packages\sqlalchemy\engine\base.py", line 143, in init
    self._dbapi_connection = engine.raw_connection()
                             ~~~~~~~~~~~~~~~~~~~~~^^
  File "C:\Users\rudolph.vanstaden\AppData\Local\Programs\Python\Python313\Lib\site-packages\sqlalchemy\engine\base.py", line 3295, in raw_connection
    return self.pool.connect()
           ~~~~~~~~~~~~~~~~~^^
  File "C:\Users\rudolph.vanstaden\AppData\Local\Programs\Python\Python313\Lib\site-packages\sqlalchemy\pool\base.py", line 447, in connect
    return _ConnectionFairy._checkout(self)

Rudolph Van Staden, [8/12/2025 12:29 PM]
~~~~~~~~~~~~~~~~~~~~~~~~^^^^^^
  File "C:\Users\rudolph.vanstaden\AppData\Local\Programs\Python\Python313\Lib\site-packages\sqlalchemy\pool\base.py", line 1264, in _checkout
    fairy = _ConnectionRecord.checkout(pool)
  File "C:\Users\rudolph.vanstaden\AppData\Local\Programs\Python\Python313\Lib\site-packages\sqlalchemy\pool\base.py", line 711, in checkout
    rec = pool._do_get()
  File "C:\Users\rudolph.vanstaden\AppData\Local\Programs\Python\Python313\Lib\site-packages\sqlalchemy\pool\impl.py", line 177, in _do_get
    with util.safe_reraise():
         ~~~~~~~~~~~~~~~^^
  File "C:\Users\rudolph.vanstaden\AppData\Local\Programs\Python\Python313\Lib\site-packages\sqlalchemy\util\langhelpers.py", line 224, in exit
    raise exc_value.with_traceback(exc_tb)
  File "C:\Users\rudolph.vanstaden\AppData\Local\Programs\Python\Python313\Lib\site-packages\sqlalchemy\pool\impl.py", line 175, in _do_get
    return self._create_connection()
           ~~~~~~~~~~~~~~~~~~~~~~~^^
  File "C:\Users\rudolph.vanstaden\AppData\Local\Programs\Python\Python313\Lib\site-packages\sqlalchemy\pool\base.py", line 388, in _create_connection
    return _ConnectionRecord(self)
  File "C:\Users\rudolph.vanstaden\AppData\Local\Programs\Python\Python313\Lib\site-packages\sqlalchemy\pool\base.py", line 673, in init
    self.connect()
    ~~~~~~~~~~~~~~^^
  File "C:\Users\rudolph.vanstaden\AppData\Local\Programs\Python\Python313\Lib\site-packages\sqlalchemy\pool\base.py", line 899, in __connect
    with util.safe_reraise():
         ~~~~~~~~~~~~~~~~~^^
  File "C:\Users\rudolph.vanstaden\AppData\Local\Programs\Python\Python313\Lib\site-packages\sqlalchemy\util\langhelpers.py", line 224, in __exit
    raise exc_value.with_traceback(exc_tb)
  File "C:\Users\rudolph.vanstaden\AppData\Local\Programs\Python\Python313\Lib\site-packages\sqlalchemy\pool\base.py", line 895, in __connect
    self.dbapi_connection = connection = pool._invoke_creator(self)
                                         ~~~~~~~~~~~~~~~~~~^^^^^^
  File "C:\Users\rudolph.vanstaden\AppData\Local\Programs\Python\Python313\Lib\site-packages\sqlalchemy\engine\create.py", line 646, in connect
    return dialect.connect(*cargs, **cparams)
           ~~~~~~~~~~~~~^^^^^^^^^^^^^^^^^^^
  File "C:\Users\rudolph.vanstaden\AppData\Local\Programs\Python\Python313\Lib\site-packages\sqlalchemy\engine\default.py", line 626, in connect
    return self.loaded_dbapi.connect(*cargs, **cparams)  # type: ignore[no-any-return]  # NOQA: E501
           ~~~~~~~~~~~~~~~~~~~~~~~~~^^^^^^^^^^^^^^^^^^^
sqlalchemy.exc.OperationalError: (sqlite3.OperationalError) unable to open database file
(Background on this error at: https://sqlalche.me/e/20/e3q8)